## 异常机制

在理想的情况下，我们的程序会按照我们的思路去运行，按理说是不会出现问题的，但是，代码实际编写后并不一定是完美的，可能会有我们没有考虑到的情况，如果这些情况能够正常得到一个错误的结果还好，但是如果直接导致程序运行出现问题了呢？

我们来看下面这段代码：

```kotlin
fun main() {
    test(1, 0) //当b为0的时候，还能正常运行吗？
}

private fun test(a: Int, b: Int): Int {
    return a / b //没有任何的判断而是直接做计算
}
```

1怎么可能去除以0呢，数学上有明确规定，0不能做除数，所以这里得到一个异常：

![image-20231227180433658](https://image.itbaima.cn/markdown/2023/12/27/Za7QPWiNso8nFXE.png)

那么这个异常到底是什么样的一种存在呢？当程序运行出现我们没有考虑到的情况时，就有可能出现异常或是错误！它们在默认情况下会强行终止我们的程序。

### 异常的使用

我们在之前其实已经接触过一些异常了，比如数组越界异常，空指针异常，算术异常等，他们其实都是异常类型，我们的每一个异常也是一个类，他们都继承自`Throwable`类！异常类型本质依然类的对象，但是异常类型支持在程序运行出现问题时抛出（也就是上面出现的红色报错）也可以提前声明，告知使用者需要处理可能会出现的异常！

每个异常对象都包含一条消息、一个堆栈跟踪和一个可选原因。

我们自己也可以抛出异常，要抛出异常对象，请使用`throw`出表达式：

```kotlin
fun main() {
  	//Exception继承自Throwable类，作为普通的异常类型
    throw Exception("牛逼")
}
```

可以看到，控制台出现了下面的报错：

![image-20231227180748601](https://image.itbaima.cn/markdown/2023/12/27/XFmHoSbZiL289EY.png)

所以，我们平时看到的那些丰富多彩的异常，其实大部分都是由程序主动抛出的。

我们也可以依葫芦画瓢，自定义我们自己的异常类：

```kotlin
class TestException(message: String) : Exception(message)

fun main() {
    throw TestException("自定义异常")
}
```

是不是感觉很简单，异常的出现就是为了方便我们快速判断程序的错误。我们可以在异常打印出来的栈追踪信息中得到当前程序出现问题的位置：

![image-20231227181629692](https://image.itbaima.cn/markdown/2023/12/27/GDpitSKX4EFIzoO.png)

这里指示的很明确，是我们的Main.kt文件第四行代码出现了异常。

### 异常的处理

当程序没有按照我们理想的样子运行而出现异常时（JVM平台下，默认会交给JVM来处理，JVM发现任何异常都会立即终止程序运行，并在控制台打印栈追踪信息）现在我们希望能够自己处理出现的问题，让程序继续运行下去，就需要对异常进行捕获，比如：

```kotlin
val array = arrayOf(1, 2, 3)
println(array[3])   //数组长度根本没有4，很明显这里会出现异常
```

现在我们希望能够手动处理这种情况，即使发生异常也要继续下去，我们可以使用try-catch语句块来完成：

```kotlin
fun main() {
    try {    //使用try-catch语句进行异常捕获
        val array = arrayOf(1, 2, 3)
        println(array[3])
    } catch (e: ArrayIndexOutOfBoundsException) {
        //因为异常本身也是一个对象，catch中实际上就是用一个局部变量去接收异常
    }
    println("程序继续正常运行！")
}
```

我们可以将代码编写到`try`语句块中，只要是在这个范围内发生的异常，都可以被捕获，使用`catch`关键字对指定的异常进行捕获，这里我们捕获的是ArrayIndexOutOfBoundsException数组越界异常：

![image-20231227182739956](https://image.itbaima.cn/markdown/2023/12/27/Qp8L7aRYuBovDfj.png)

可以看到，当我们捕获异常之后，程序可以继续正常运行，并不会像之前一样直接结束掉。

注意，catch中捕获的类型只能是Throwable的子类，也就是说要么是抛出的异常，要么是错误，不能是其他的任何类型。

我们可以在`catch`语句块中对捕获到的异常进行处理：

```kotlin
fun main() {
    try {    //使用try-catch语句进行异常捕获
        val array = arrayOf(1, 2, 3)
        println(array[3])
    } catch (e: ArrayIndexOutOfBoundsException) {
        e.printStackTrace();   //打印栈追踪信息
        println("异常错误信息："+e.message);   //获取异常的错误信息
    }
    println("程序继续正常运行！")
}
```

![image-20231227182840106](https://image.itbaima.cn/markdown/2023/12/27/39GBhcEr54I8blv.png)

当代码可能出现多种类型的异常时，我们希望能够分不同情况处理不同类型的异常，就可以使用多重异常捕获：

```kotlin
try {
    //....
} catch (e: Exception) {  //父类型在前，会将子类的也捕获
  
} catch (e: NullPointerException) {   //因为NullPointerException是Exception的子类型，永远都不会进入这里
  
} catch (e: IndexOutOfBoundsException) {   //永远都不会进入这里
  
}
```

最后，当我们希望，程序运行时，无论是否出现异常，都会在最后执行任务，可以交给`finally`语句块来处理：

```kotlin
try {
    //....
} catch (e: Exception) {
    
} finally {
    println("lbwnb") //无论是否出现异常，都会在最后执行
}
```

注意：`try`语句块至少要配合`catch`或`finally`中的一个。

`try`也可以当做一个表达式使用，这意味着它可以有一个返回值：

```kotlin
fun main() {
    val input = readln()
    val a: Int? = try { input.toInt() } catch (e: NumberFormatException) { null }
    println(a)
}
```

针对于空类型，我们也可以在判断为空时直接抛出异常：

```kotlin
val s = person.name ?: throw IllegalArgumentException("Name required")
```

至此，有关Kotlin基础语言部分就全部完结了，后面我们还会继续讲解Kotlin的更多扩展知识，包括Kotlin与Java的交互、Kotlin协程、Kotlin反射等等，感谢各位小伙伴一直以来的支持。

